<?xml version="1.0" ?>
<!-- =================================================================================== -->
<!-- |    This document was autogenerated by xacro from inof_robot.urdf.xacro          | -->
<!-- |    EDITING THIS FILE BY HAND IS NOT RECOMMENDED                                 | -->
<!-- =================================================================================== -->
<robot name="inof">
  <gazebo>
    <plugin filename="libgazebo_ros_control.so" name="gazebo_ros_control">
      <robotNamespace>/inof</robotNamespace>
    </plugin>
  </gazebo>
  <material name="white_tr">
    <color rgba="1 1 1 1"/>
  </material>
  <material name="blackish">
    <color rgba="0 0 0.8 1"/>
  </material>
  <material name="black">
    <color rgba="0 0 0 1"/>
  </material>
  <link name="layer0">
    <visual>
      <origin rpy="0 0 0" xyz="0 0 0.025"/>
      <geometry>
        <cylinder length="0.002" radius="0.075"/>
      </geometry>
      <material name="white_tr"/>
    </visual>
    <collision>
      <origin rpy="0 0 0" xyz="0 0 0.025"/>
      <geometry>
        <cylinder length="0.002" radius="0.075"/>
      </geometry>
    </collision>
    <inertial>
      <origin rpy="0 0 0" xyz="0 0 0.025"/>
      <mass value="0.0378169"/>
      <inertia ixx="5.3192621258333326e-05" ixy="0" ixz="0" iyy="5.3192621258333326e-05" iyz="0" izz="0.00010636003125"/>
    </inertial>
  </link>
  <gazebo reference="layer0">
    <material>Gazebo/BlackTransparent</material>
  </gazebo>
  <link name="support_leg0">
    <visual>
      <origin rpy="0 0 0" xyz="0 0 0.025"/>
      <geometry>
        <cylinder length="0.05" radius="0.003"/>
      </geometry>
      <material name="blackish"/>
    </visual>
    <collision>
      <origin rpy="0 0 0" xyz="0 0 0.025"/>
      <geometry>
        <cylinder length="0.05" radius="0.003"/>
      </geometry>
    </collision>
    <inertial>
      <origin rpy="0 0 0" xyz="0 0 0.025"/>
      <mass value="0.0015127"/>
      <inertia ixx="3.1854940833333343e-07" ixy="0" ixz="0" iyy="3.1854940833333343e-07" iyz="0" izz="6.807150000000001e-09"/>
    </inertial>
  </link>
  <link name="support_leg1">
    <visual>
      <origin rpy="0 0 0" xyz="0 0 0.025"/>
      <geometry>
        <cylinder length="0.05" radius="0.003"/>
      </geometry>
      <material name="blackish"/>
    </visual>
    <collision>
      <origin rpy="0 0 0" xyz="0 0 0.025"/>
      <geometry>
        <cylinder length="0.05" radius="0.003"/>
      </geometry>
    </collision>
    <inertial>
      <origin rpy="0 0 0" xyz="0 0 0.025"/>
      <mass value="0.0015127"/>
      <inertia ixx="3.1854940833333343e-07" ixy="0" ixz="0" iyy="3.1854940833333343e-07" iyz="0" izz="6.807150000000001e-09"/>
    </inertial>
  </link>
  <link name="support_leg2">
    <visual>
      <origin rpy="0 0 0" xyz="0 0 0.025"/>
      <geometry>
        <cylinder length="0.05" radius="0.003"/>
      </geometry>
      <material name="blackish"/>
    </visual>
    <collision>
      <origin rpy="0 0 0" xyz="0 0 0.025"/>
      <geometry>
        <cylinder length="0.05" radius="0.003"/>
      </geometry>
    </collision>
    <inertial>
      <origin rpy="0 0 0" xyz="0 0 0.025"/>
      <mass value="0.0015127"/>
      <inertia ixx="3.1854940833333343e-07" ixy="0" ixz="0" iyy="3.1854940833333343e-07" iyz="0" izz="6.807150000000001e-09"/>
    </inertial>
  </link>
  <link name="support_leg3">
    <visual>
      <origin rpy="0 0 0" xyz="0 0 0.025"/>
      <geometry>
        <cylinder length="0.05" radius="0.003"/>
      </geometry>
      <material name="blackish"/>
    </visual>
    <collision>
      <origin rpy="0 0 0" xyz="0 0 0.025"/>
      <geometry>
        <cylinder length="0.05" radius="0.003"/>
      </geometry>
    </collision>
    <inertial>
      <origin rpy="0 0 0" xyz="0 0 0.025"/>
      <mass value="0.0015127"/>
      <inertia ixx="3.1854940833333343e-07" ixy="0" ixz="0" iyy="3.1854940833333343e-07" iyz="0" izz="6.807150000000001e-09"/>
    </inertial>
  </link>
  <link name="layer1">
    <visual>
      <origin rpy="0 0 0" xyz="0 0 0"/>
      <geometry>
        <cylinder length="0.002" radius="0.075"/>
      </geometry>
      <material name="white_tr"/>
    </visual>
    <collision>
      <origin rpy="0 0 0" xyz="0 0 0"/>
      <geometry>
        <cylinder length="0.002" radius="0.075"/>
      </geometry>
    </collision>
    <inertial>
      <origin rpy="0 0 0" xyz="0 0 0"/>
      <mass value="0.0378169"/>
      <inertia ixx="5.3192621258333326e-05" ixy="0" ixz="0" iyy="5.3192621258333326e-05" iyz="0" izz="0.00010636003125"/>
    </inertial>
  </link>
  <gazebo reference="layer1">
    <material>Gazebo/BlackTransparent</material>
  </gazebo>
  <link name="wheelr">
    <visual>
      <origin rpy="0 1.5707963267948966 0" xyz="0 0 0"/>
      <geometry>
        <cylinder length="0.004" radius="0.025"/>
      </geometry>
      <material name="black"/>
    </visual>
    <collision>
      <origin rpy="0 1.5707963267948966 0" xyz="0 0 0"/>
      <geometry>
        <cylinder length="0.004" radius="0.025"/>
      </geometry>
    </collision>
    <inertial>
      <origin rpy="0 1.5707963267948966 0" xyz="0 0 0"/>
      <mass value="0.0084038"/>
      <inertia ixx="1.3242988166666667e-06" ixy="0" ixz="0" iyy="1.3242988166666667e-06" iyz="0" izz="2.6261875000000003e-06"/>
    </inertial>
  </link>
  <gazebo reference="wheelr">
    <mu1>200.0</mu1>
    <mu2>100.0</mu2>
    <kp> 10000000.0</kp>
    <kd> 1.0</kd>
    <material>Gazebo/Grey</material>
  </gazebo>
  <link name="wheell">
    <visual>
      <origin rpy="0 1.5707963267948966 0" xyz="0 0 0"/>
      <geometry>
        <cylinder length="0.004" radius="0.025"/>
      </geometry>
      <material name="black"/>
    </visual>
    <collision>
      <origin rpy="0 1.5707963267948966 0" xyz="0 0 0"/>
      <geometry>
        <cylinder length="0.004" radius="0.025"/>
      </geometry>
    </collision>
    <inertial>
      <origin rpy="0 1.5707963267948966 0" xyz="0 0 0"/>
      <mass value="0.0084038"/>
      <inertia ixx="1.3242988166666667e-06" ixy="0" ixz="0" iyy="1.3242988166666667e-06" iyz="0" izz="2.6261875000000003e-06"/>
    </inertial>
  </link>
  <gazebo reference="wheell">
    <mu1>200.0</mu1>
    <mu2>100.0</mu2>
    <kp> 10000000.0</kp>
    <kd> 1.0</kd>
    <material>Gazebo/Grey</material>
  </gazebo>
  <link name="caster_wheel0">
    <visual>
      <origin rpy="0 0 0" xyz="0 0 -0.011875"/>
      <geometry>
        <box size="0.012 0.012 0.02375"/>
      </geometry>
      <material name="black"/>
    </visual>
    <collision>
      <origin rpy="0 0 0" xyz="0 0 -0.011875"/>
      <geometry>
        <box size="0.012 0.012 0.02375"/>
      </geometry>
    </collision>
    <inertial>
      <origin rpy="0 0 0" xyz="0 0 -0.011875"/>
      <mass value="0.0036594"/>
      <inertia ixx="2.1592365937500002e-07" ixy="0" ixz="0" iyy="2.1592365937500002e-07" iyz="0" izz="5.269536e-07"/>
    </inertial>
  </link>
  <!--gazebo reference="caster_wheel${num}">
			<material>Gazebo/${c}</material>
		</gazebo-->
  <link name="caster_wheel1">
    <visual>
      <origin rpy="0 0 0" xyz="0 0 -0.011875"/>
      <geometry>
        <box size="0.012 0.012 0.02375"/>
      </geometry>
      <material name="black"/>
    </visual>
    <collision>
      <origin rpy="0 0 0" xyz="0 0 -0.011875"/>
      <geometry>
        <box size="0.012 0.012 0.02375"/>
      </geometry>
    </collision>
    <inertial>
      <origin rpy="0 0 0" xyz="0 0 -0.011875"/>
      <mass value="0.0036594"/>
      <inertia ixx="2.1592365937500002e-07" ixy="0" ixz="0" iyy="2.1592365937500002e-07" iyz="0" izz="5.269536e-07"/>
    </inertial>
  </link>
  <!--gazebo reference="caster_wheel${num}">
			<material>Gazebo/${c}</material>
		</gazebo-->
  <joint name="layer0_wheell_joint" type="continuous">
    <parent link="layer0"/>
    <child link="wheell"/>
    <origin rpy="0 0 1.5707963267948966" xyz="0 0.077 0.025"/>
    <axis rpy="0 0 0" xyz="1 0 0"/>
  </joint>
  <joint name="layer0_wheelr_joint" type="continuous">
    <parent link="layer0"/>
    <child link="wheelr"/>
    <origin rpy="0 0 1.5707963267948966" xyz="0 -0.077 0.025"/>
    <axis rpy="0 0 0" xyz="1 0 0"/>
  </joint>
  <joint name="layer0_support0_joint" type="fixed">
    <parent link="layer0"/>
    <child link="support_leg0"/>
    <origin xyz="0.04772970773009196 0.047729707730091955 0.025"/>
  </joint>
  <joint name="layer0_support1_joint" type="fixed">
    <parent link="layer0"/>
    <child link="support_leg1"/>
    <origin xyz="-0.047729707730091955 0.04772970773009196 0.025"/>
  </joint>
  <joint name="layer0_support2_joint" type="fixed">
    <parent link="layer0"/>
    <child link="support_leg2"/>
    <origin xyz="-0.04772970773009197 -0.047729707730091955 0.025"/>
  </joint>
  <joint name="layer0_support3_joint" type="fixed">
    <parent link="layer0"/>
    <child link="support_leg3"/>
    <origin xyz="0.04772970773009195 -0.04772970773009197 0.025"/>
  </joint>
  <joint name="support0_layer1_joint" type="fixed">
    <child link="layer1"/>
    <parent link="support_leg0"/>
    <origin xyz="-0.04772970773009196 -0.047729707730091955 0.05"/>
  </joint>
  <joint name="layer0_caster0" type="fixed">
    <child link="caster_wheel0"/>
    <parent link="layer0"/>
    <origin xyz="0.0675 4.133182947122317e-18 0.025"/>
  </joint>
  <joint name="layer0_caster1" type="fixed">
    <child link="caster_wheel1"/>
    <parent link="layer0"/>
    <origin xyz="-0.0675 -1.2399548841366951e-17 0.025"/>
  </joint>
  <transmission name="wheelr_trans">
    <type>transmission_interface/SimpleTransmission</type>
    <actuator name="$wheelr_motor">
      <mechanicalReduction>1</mechanicalReduction>
      <hardwareInterface>hardware_interface/VelocityJointInterface</hardwareInterface>
    </actuator>
    <joint name="layer0_wheelr_joint">
      <hardwareInterface>hardware_interface/VelocityJointInterface</hardwareInterface>
    </joint>
  </transmission>
  <transmission name="wheell_trans">
    <type>transmission_interface/SimpleTransmission</type>
    <actuator name="$wheell_motor">
      <mechanicalReduction>1</mechanicalReduction>
      <hardwareInterface>hardware_interface/VelocityJointInterface</hardwareInterface>
    </actuator>
    <joint name="layer0_wheell_joint">
      <hardwareInterface>hardware_interface/VelocityJointInterface</hardwareInterface>
    </joint>
  </transmission>
</robot>
